WARNING 2018-06-25 19:41:33,587 base 93 Not Found: /
WARNING 2018-06-25 19:41:33,589 basehttp 124 "GET / HTTP/1.1" 404 2114
WARNING 2018-06-25 19:41:34,471 base 93 Not Found: /favicon.ico
WARNING 2018-06-25 19:41:34,474 basehttp 124 "GET /favicon.ico HTTP/1.1" 404 2165
WARNING 2018-06-25 19:42:55,198 base 93 Not Found: /image_codes/1
WARNING 2018-06-25 19:42:55,206 basehttp 124 "GET /image_codes/1 HTTP/1.1" 404 2171
WARNING 2018-06-25 19:44:32,188 base 93 Not Found: /image_codes/1
WARNING 2018-06-25 19:44:32,191 basehttp 124 "GET /image_codes/1 HTTP/1.1" 404 2171
WARNING 2018-06-25 19:44:40,951 base 93 Not Found: /
WARNING 2018-06-25 19:44:40,955 basehttp 124 "GET / HTTP/1.1" 404 2114
WARNING 2018-06-25 19:44:53,173 base 93 Not Found: /image_codes/1
WARNING 2018-06-25 19:44:53,178 basehttp 124 "GET /image_codes/1 HTTP/1.1" 404 2171
WARNING 2018-06-25 19:46:01,604 base 93 Not Found: /image_codes/1
WARNING 2018-06-25 19:46:01,610 basehttp 124 "GET /image_codes/1 HTTP/1.1" 404 2171
WARNING 2018-06-25 19:46:47,227 base 93 Not Found: /image_codes/1/
WARNING 2018-06-25 19:46:47,230 basehttp 124 "GET /image_codes/1/ HTTP/1.1" 404 2174
INFO 2018-06-25 19:47:59,738 basehttp 124 "GET /admin HTTP/1.1" 301 0
INFO 2018-06-25 19:47:59,834 basehttp 124 "GET /admin/ HTTP/1.1" 302 0
INFO 2018-06-25 19:48:00,453 basehttp 124 "GET /admin/login/?next=/admin/ HTTP/1.1" 200 1857
INFO 2018-06-25 19:48:00,563 basehttp 124 "GET /static/admin/css/base.css HTTP/1.1" 200 16106
INFO 2018-06-25 19:48:00,564 basehttp 124 "GET /static/admin/css/login.css HTTP/1.1" 200 1203
INFO 2018-06-25 19:48:00,590 basehttp 124 "GET /static/admin/css/responsive.css HTTP/1.1" 200 17894
INFO 2018-06-25 19:48:00,792 basehttp 124 "GET /static/admin/css/fonts.css HTTP/1.1" 200 423
INFO 2018-06-25 19:48:00,900 basehttp 124 "GET /static/admin/fonts/Roboto-Regular-webfont.woff HTTP/1.1" 200 80304
INFO 2018-06-25 19:48:01,026 basehttp 124 "GET /static/admin/fonts/Roboto-Light-webfont.woff HTTP/1.1" 200 81348
INFO 2018-06-25 19:48:04,452 basehttp 124 "GET /admin/ HTTP/1.1" 302 0
INFO 2018-06-25 19:48:04,599 basehttp 124 "GET /admin/login/?next=/admin/ HTTP/1.1" 200 1857
INFO 2018-06-25 19:48:08,548 basehttp 124 "GET /admin HTTP/1.1" 301 0
INFO 2018-06-25 19:48:08,566 basehttp 124 "GET /admin/ HTTP/1.1" 302 0
INFO 2018-06-25 19:48:08,665 basehttp 124 "GET /admin/login/?next=/admin/ HTTP/1.1" 200 1857
WARNING 2018-06-25 19:48:27,112 base 93 Not Found: /image_codes/1
WARNING 2018-06-25 19:48:27,125 basehttp 124 "GET /image_codes/1 HTTP/1.1" 404 2171
INFO 2018-06-25 19:51:39,614 basehttp 124 "GET /image_codes/1 HTTP/1.1" 301 0
ERROR 2018-06-25 19:51:39,656 exception 118 Internal Server Error: /image_codes/1/
Traceback (most recent call last):
  File "/home/python/.virtualenvs/django_py3/lib/python3.5/site-packages/rest_framework/views.py", line 480, in dispatch
    response = handler(request, *args, **kwargs)
  File "/home/python/Desktop/django/meiduo_mall/meiduo_mall/apps/verification/views.py", line 12, in get
    text,image  = captcha.generate_captcha()
AttributeError: module 'meiduo_mall.libs.captcha' has no attribute 'generate_captcha'

During handling of the above exception, another exception occurred:

Traceback (most recent call last):
  File "/home/python/.virtualenvs/django_py3/lib/python3.5/site-packages/rest_framework/settings.py", line 183, in import_from_string
    module = import_module(module_path)
  File "/home/python/.virtualenvs/django_py3/lib/python3.5/importlib/__init__.py", line 126, in import_module
    return _bootstrap._gcd_import(name[level:], package, level)
  File "<frozen importlib._bootstrap>", line 986, in _gcd_import
  File "<frozen importlib._bootstrap>", line 969, in _find_and_load
  File "<frozen importlib._bootstrap>", line 956, in _find_and_load_unlocked
ImportError: No module named 'meiduo_mall.utils.exceptions'

During handling of the above exception, another exception occurred:

Traceback (most recent call last):
  File "/home/python/.virtualenvs/django_py3/lib/python3.5/site-packages/django/core/handlers/exception.py", line 35, in inner
    response = get_response(request)
  File "/home/python/.virtualenvs/django_py3/lib/python3.5/site-packages/django/core/handlers/base.py", line 128, in _get_response
    response = self.process_exception_by_middleware(e, request)
  File "/home/python/.virtualenvs/django_py3/lib/python3.5/site-packages/django/core/handlers/base.py", line 126, in _get_response
    response = wrapped_callback(request, *callback_args, **callback_kwargs)
  File "/home/python/.virtualenvs/django_py3/lib/python3.5/site-packages/django/views/decorators/csrf.py", line 54, in wrapped_view
    return view_func(*args, **kwargs)
  File "/home/python/.virtualenvs/django_py3/lib/python3.5/site-packages/django/views/generic/base.py", line 69, in view
    return self.dispatch(request, *args, **kwargs)
  File "/home/python/.virtualenvs/django_py3/lib/python3.5/site-packages/rest_framework/views.py", line 483, in dispatch
    response = self.handle_exception(exc)
  File "/home/python/.virtualenvs/django_py3/lib/python3.5/site-packages/rest_framework/views.py", line 437, in handle_exception
    exception_handler = self.get_exception_handler()
  File "/home/python/.virtualenvs/django_py3/lib/python3.5/site-packages/rest_framework/views.py", line 288, in get_exception_handler
    return self.settings.EXCEPTION_HANDLER
  File "/home/python/.virtualenvs/django_py3/lib/python3.5/site-packages/rest_framework/settings.py", line 227, in __getattr__
    val = perform_import(val, attr)
  File "/home/python/.virtualenvs/django_py3/lib/python3.5/site-packages/rest_framework/settings.py", line 170, in perform_import
    return import_from_string(val, setting_name)
  File "/home/python/.virtualenvs/django_py3/lib/python3.5/site-packages/rest_framework/settings.py", line 187, in import_from_string
    raise ImportError(msg)
ImportError: Could not import 'meiduo_mall.utils.exceptions.exception_handler' for API setting 'EXCEPTION_HANDLER'. ImportError: No module named 'meiduo_mall.utils.exceptions'.
ERROR 2018-06-25 19:51:40,319 basehttp 124 "GET /image_codes/1/ HTTP/1.1" 500 127967
ERROR 2018-06-25 19:53:01,110 exception 118 Internal Server Error: /image_codes/1/
Traceback (most recent call last):
  File "/home/python/.virtualenvs/django_py3/lib/python3.5/site-packages/django/core/handlers/exception.py", line 35, in inner
    response = get_response(request)
  File "/home/python/.virtualenvs/django_py3/lib/python3.5/site-packages/django/core/handlers/base.py", line 128, in _get_response
    response = self.process_exception_by_middleware(e, request)
  File "/home/python/.virtualenvs/django_py3/lib/python3.5/site-packages/django/core/handlers/base.py", line 126, in _get_response
    response = wrapped_callback(request, *callback_args, **callback_kwargs)
  File "/home/python/.virtualenvs/django_py3/lib/python3.5/site-packages/django/views/decorators/csrf.py", line 54, in wrapped_view
    return view_func(*args, **kwargs)
  File "/home/python/.virtualenvs/django_py3/lib/python3.5/site-packages/django/views/generic/base.py", line 69, in view
    return self.dispatch(request, *args, **kwargs)
  File "/home/python/.virtualenvs/django_py3/lib/python3.5/site-packages/rest_framework/views.py", line 483, in dispatch
    response = self.handle_exception(exc)
  File "/home/python/.virtualenvs/django_py3/lib/python3.5/site-packages/rest_framework/views.py", line 443, in handle_exception
    self.raise_uncaught_exception(exc)
  File "/home/python/.virtualenvs/django_py3/lib/python3.5/site-packages/rest_framework/views.py", line 480, in dispatch
    response = handler(request, *args, **kwargs)
  File "/home/python/Desktop/django/meiduo_mall/meiduo_mall/apps/verification/views.py", line 12, in get
    text,image  = captcha.generate_captcha()
AttributeError: module 'meiduo_mall.libs.captcha' has no attribute 'generate_captcha'
ERROR 2018-06-25 19:53:01,695 basehttp 124 "GET /image_codes/1/ HTTP/1.1" 500 96900
ERROR 2018-06-25 20:21:44,777 excptions 25 [<verification.views.imagecodeid object at 0x7f114559b860>] Error 111 connecting to 10.211.55.5:6379. Connection refused.
ERROR 2018-06-25 20:21:44,879 basehttp 124 "GET /image_codes/1/ HTTP/1.1" 507 5186
INFO 2018-06-25 20:21:44,960 basehttp 124 "GET /static/rest_framework/css/bootstrap.min.css HTTP/1.1" 200 121200
INFO 2018-06-25 20:21:45,028 basehttp 124 "GET /static/rest_framework/css/bootstrap-tweaks.css HTTP/1.1" 200 3385
INFO 2018-06-25 20:21:45,035 basehttp 124 "GET /static/rest_framework/css/prettify.css HTTP/1.1" 200 817
INFO 2018-06-25 20:21:45,041 basehttp 124 "GET /static/rest_framework/css/default.css HTTP/1.1" 200 1131
INFO 2018-06-25 20:21:45,062 basehttp 124 "GET /static/rest_framework/js/ajax-form.js HTTP/1.1" 200 3597
INFO 2018-06-25 20:21:45,072 basehttp 124 "GET /static/rest_framework/js/jquery-3.3.1.min.js HTTP/1.1" 200 86927
INFO 2018-06-25 20:21:45,072 basehttp 124 "GET /static/rest_framework/js/csrf.js HTTP/1.1" 200 1735
INFO 2018-06-25 20:21:45,140 basehttp 124 "GET /static/rest_framework/js/bootstrap.min.js HTTP/1.1" 200 37045
INFO 2018-06-25 20:21:45,164 basehttp 124 "GET /static/rest_framework/js/prettify-min.js HTTP/1.1" 200 13632
INFO 2018-06-25 20:21:45,165 basehttp 124 "GET /static/rest_framework/js/default.js HTTP/1.1" 200 1262
INFO 2018-06-25 20:21:45,403 basehttp 124 "GET /static/rest_framework/img/grid.png HTTP/1.1" 200 1458
ERROR 2018-06-25 20:26:57,500 excptions 25 [<verification.views.imagecodeid object at 0x7f113f455978>] Error 111 connecting to 10.211.55.5:6379. Connection refused.
ERROR 2018-06-25 20:26:57,553 basehttp 124 "GET /image_codes/1/ HTTP/1.1" 507 5186
WARNING 2018-06-25 20:29:17,134 base 93 Not Found: /image_codes/1/
WARNING 2018-06-25 20:29:17,142 basehttp 124 "GET /image_codes/1/ HTTP/1.1" 404 2167
ERROR 2018-06-26 00:21:23,532 exception 118 Internal Server Error: /image_codes/1/
Traceback (most recent call last):
  File "/home/python/.virtualenvs/django_py3/lib/python3.5/site-packages/django/core/handlers/exception.py", line 35, in inner
    response = get_response(request)
  File "/home/python/.virtualenvs/django_py3/lib/python3.5/site-packages/django/core/handlers/base.py", line 128, in _get_response
    response = self.process_exception_by_middleware(e, request)
  File "/home/python/.virtualenvs/django_py3/lib/python3.5/site-packages/django/core/handlers/base.py", line 126, in _get_response
    response = wrapped_callback(request, *callback_args, **callback_kwargs)
  File "/home/python/.virtualenvs/django_py3/lib/python3.5/site-packages/django/views/decorators/csrf.py", line 54, in wrapped_view
    return view_func(*args, **kwargs)
  File "/home/python/.virtualenvs/django_py3/lib/python3.5/site-packages/django/views/generic/base.py", line 69, in view
    return self.dispatch(request, *args, **kwargs)
  File "/home/python/.virtualenvs/django_py3/lib/python3.5/site-packages/rest_framework/views.py", line 483, in dispatch
    response = self.handle_exception(exc)
  File "/home/python/.virtualenvs/django_py3/lib/python3.5/site-packages/rest_framework/views.py", line 443, in handle_exception
    self.raise_uncaught_exception(exc)
  File "/home/python/.virtualenvs/django_py3/lib/python3.5/site-packages/rest_framework/views.py", line 480, in dispatch
    response = handler(request, *args, **kwargs)
TypeError: get() got an unexpected keyword argument 'image_code_id'
ERROR 2018-06-26 00:21:24,045 basehttp 124 "GET /image_codes/1/ HTTP/1.1" 500 93028
ERROR 2018-06-26 00:23:22,367 excptions 25 [<verification.views.imagecodeid object at 0x7f6588445da0>] Error 111 connecting to 10.211.55.5:6379. Connection refused.
ERROR 2018-06-26 00:23:22,464 basehttp 124 "GET /image_codes/1/ HTTP/1.1" 507 5186
ERROR 2018-06-26 00:23:56,953 excptions 25 [<verification.views.imagecodeid object at 0x7f658816e0f0>] Error 111 connecting to 10.211.55.5:6379. Connection refused.
ERROR 2018-06-26 00:23:57,057 basehttp 124 "GET /image_codes/1/ HTTP/1.1" 507 5186
INFO 2018-06-26 00:24:05,624 basehttp 124 "GET /image_codes/1/ HTTP/1.1" 200 3089
INFO 2018-06-26 00:57:33,765 basehttp 124 "GET /image_codes/1/ HTTP/1.1" 200 3702
INFO 2018-06-26 00:59:51,111 basehttp 124 "GET /image_codes/6394b241-3744-460d-ab20-bc83305a600a/ HTTP/1.1" 200 3026
